Workbook
Name Data: 'Quality Control Dashboard '!$L$151:$L$159

Sheet Quality Control Dashboard   
J1: Quality Control KPI Dashboard
A2: Quality Management.
A3: Quality Control Dep.
A4: Production hall : 1_2_3
A5: Date of Report :
C8: m
A9: عرض العيوب الرئيسية ومتوسط الأوزان فى المنتج النهائى صالة 1 وصالة 2 وصالة 3
D11: M1-1 | E11: M2-1 | F11: M3-2 | G11: M4-2 | H11: M5-3 | I11: M6-3 | J11: M7-3 | K11: M8-4 | L11: M9-5 | M11: M10-6 | N11: M10-6 | O11: M18-13 | T11: M11-7 | U11: M12-7 | V11: M13-8 | W11: M13-8 | X11: M14-9 | Y11: M15-10 | Z11: M16-11 | AA11: M16-11 | AB11: M17-12 | AC11: M17-12 | AI11: M11-7 | AJ11: M12-7 | AK11: M13-8 | AL11: M13-8 | AM11: M14-9 | AN11: M15-10 | AO11: M16-11 | AP11: M16-11 | AQ11: M17-12 | AR11: M17-12
A12: السبت | C12: اسم المنتج | D12: ='QC Deviation Record Hall 1 '!C5 -> 0 | E12: ='QC Deviation Record Hall 1 '!K5 -> 0 | F12: ='QC Deviation Record Hall 1 '!S5 -> 0 | G12: ='QC Deviation Record Hall 1 '!AA5 -> 0 | H12: ='QC Deviation Record Hall 1 '!AI5 -> 0 | I12: ='QC Deviation Record Hall 1 '!AQ5 -> 0 | J12: ='QC Deviation Record Hall 1 '!AY5 -> 0 | K12: ='QC Deviation Record Hall 1 '!BG5 -> 0 | L12: ='QC Deviation Record Hall 1 '!BO5 -> 0 | M12: ='QC Deviation Record Hall 1 '!BW5 -> 0 | N12: ='QC Deviation Record Hall 1 '!CE5 -> 0 | O12: ='QC Deviation Record Hall 1 '!CM5 -> 0 | Q12: السبت | S12: اسم المنتج | T12: ='QC Deviation Record Hall 2'!C4 -> 0 | U12: ='QC Deviation Record Hall 2'!K4 -> 0 | V12: ='QC Deviation Record Hall 2'!S4 -> 0 | W12: ='QC Deviation Record Hall 2'!AA4 -> 0 | X12: ='QC Deviation Record Hall 2'!AI4 -> 0 | Y12: ='QC Deviation Record Hall 2'!AQ4 -> 0 | Z12: ='QC Deviation Record Hall 2'!AY4 -> 0 | AA12: ='QC Deviation Record Hall 2'!BG4 -> 0 | AB12: ='QC Deviation Record Hall 2'!BO4 -> 0 | AC12: ='QC Deviation Record Hall 2'!BW4 -> 0 | AF12: السبت | AH12: اسم المنتج | AI12: ='QC Deviation Record Hall 3'!C4 -> 0 | AJ12: ='QC Deviation Record Hall 3'!K4 -> 0 | AK12: ='QC Deviation Record Hall 3'!S4 -> 0 | AL12: ='QC Deviation Record Hall 3'!AA4 -> 0 | AM12: ='QC Deviation Record Hall 3'!AI4 -> 0 | AN12: ='QC Deviation Record Hall 3'!AQ4 -> 0 | AO12: ='QC Deviation Record Hall 3'!AY4 -> 0 | AP12: ='QC Deviation Record Hall 3'!BG4 -> 0 | AQ12: ='QC Deviation Record Hall 3'!BO4 -> 0 | AR12: ='QC Deviation Record Hall 3'!BW4 -> 0
C13: مدى الوزن | S13: مدى الوزن | AH13: مدى الوزن
C14: متوسط الوزن | D14: =IFERROR(AVERAGE('QC Record Production Hall 1'!L6:L8),"") | E14: =IFERROR(AVERAGE('QC Record Production Hall 1'!Z6:Z8),"") | F14: =IFERROR(AVERAGE('QC Record Production Hall 1'!AN6:AN8),"") | G14: =IFERROR(AVERAGE('QC Record Production Hall 1'!BB6:BB8),"") | H14: =IFERROR(AVERAGE('QC Record Production Hall 1'!J30:J32),"") | I14: =IFERROR(AVERAGE('QC Record Production Hall 1'!V30:V32),"") | J14: =IFERROR(AVERAGE('QC Record Production Hall 1'!AN30:AN32),"") | K14: =IFERROR(AVERAGE('QC Record Production Hall 1'!BB30:BB32),"") | L14: =IFERROR(AVERAGE('QC Record Production Hall 1'!J54:J56),"") | M14: =IFERROR(AVERAGE('QC Record Production Hall 1'!W54:W56),"") | N14: =IFERROR(AVERAGE('QC Record Production Hall 1'!AK54:AK56),"") | O14: =IFERROR(AVERAGE('QC Record Production Hall 1'!AX54:AX56),"") | S14: متوسط الوزن | T14: =IFERROR(AVERAGE('QC Record Production Hall 2'!J6:J8),"") | U14: =IFERROR(AVERAGE('QC Record Production Hall 2'!V6:V8),"") | V14: =IFERROR(AVERAGE('QC Record Production Hall 2'!AG6:AG8),"") | W14: =IFERROR(AVERAGE('QC Record Production Hall 2'!AR6:AR8),"") | X14: =IFERROR(AVERAGE('QC Record Production Hall 2'!L30:L32),"") | Y14: =IFERROR(AVERAGE('QC Record Production Hall 2'!AD30:AD32),"") | Z14: =IFERROR(AVERAGE('QC Record Production Hall 2'!BC6:BC8),"") | AA14: =IFERROR(AVERAGE('QC Record Production Hall 2'!BN6:BN8),"") | AB14: =IFERROR(AVERAGE('QC Record Production Hall 2'!AR30:AR32),"") | AC14: =IFERROR(AVERAGE('QC Record Production Hall 2'!BC30:BC32),"") | AH14: متوسط الوزن | AI14: =IFERROR(AVERAGE('QC Record Production Hall 3'!J6:J8),"") | AJ14: =IFERROR(AVERAGE('QC Record Production Hall 3'!V6:V8),"") | AK14: =IFERROR(AVERAGE('QC Record Production Hall 3'!AG6:AG8),"") | AL14: =IFERROR(AVERAGE('QC Record Production Hall 3'!AR6:AR8),"") | AM14: =IFERROR(AVERAGE('QC Record Production Hall 3'!L30:L32),"") | AN14: =IFERROR(AVERAGE('QC Record Production Hall 3'!AD30:AD32),"") | AO14: =IFERROR(AVERAGE('QC Record Production Hall 3'!BC6:BC8),"") | AP14: =IFERROR(AVERAGE('QC Record Production Hall 3'!BN6:BN8),"") | AQ14: =IFERROR(AVERAGE('QC Record Production Hall 3'!AR30:AR32),"") | AR14: =IFERROR(AVERAGE('QC Record Production Hall 3'!BC30:BC32),"")
A15: الأحد | C15: اسم المنتج | D15: ='QC Deviation Record Hall 1 '!D5 -> 0 | E15: ='QC Deviation Record Hall 1 '!L5 -> 0 | F15: ='QC Deviation Record Hall 1 '!T5 -> 0 | G15: ='QC Deviation Record Hall 1 '!AB5 -> 0 | H15: ='QC Deviation Record Hall 1 '!AJ5 -> 0 | I15: ='QC Deviation Record Hall 1 '!AR5 -> 0 | J15: ='QC Deviation Record Hall 1 '!AZ5 -> 0 | K15: ='QC Deviation Record Hall 1 '!BH5 -> 0 | L15: ='QC Deviation Record Hall 1 '!BP5 -> 0 | M15: ='QC Deviation Record Hall 1 '!BX5 -> 0 | N15: ='QC Deviation Record Hall 1 '!CF5 -> 0 | O15: ='QC Deviation Record Hall 1 '!CN5 -> 0 | Q15: الأحد | S15: اسم المنتج | T15: ='QC Deviation Record Hall 2'!D4 -> 0 | U15: ='QC Deviation Record Hall 2'!L4 -> 0 | V15: ='QC Deviation Record Hall 2'!T4 -> 0 | W15: ='QC Deviation Record Hall 2'!AB4 -> 0 | X15: ='QC Deviation Record Hall 2'!AJ4 -> 0 | Y15: ='QC Deviation Record Hall 2'!AR4 -> 0 | Z15: ='QC Deviation Record Hall 2'!AZ4 -> 0 | AA15: ='QC Deviation Record Hall 2'!BH4 -> 0 | AB15: ='QC Deviation Record Hall 2'!BP4 -> 0 | AC15: ='QC Deviation Record Hall 2'!BX4 -> 0 | AF15: الأحد | AH15: اسم المنتج | AI15: ='QC Deviation Record Hall 3'!D4 -> 0 | AJ15: ='QC Deviation Record Hall 3'!L4 -> 0 | AK15: ='QC Deviation Record Hall 3'!T4 -> 0 | AL15: ='QC Deviation Record Hall 3'!AB4 -> 0 | AM15: ='QC Deviation Record Hall 3'!AJ4 -> 0 | AN15: ='QC Deviation Record Hall 3'!AR4 -> 0 | AO15: ='QC Deviation Record Hall 3'!AZ4 -> 0 | AP15: ='QC Deviation Record Hall 3'!BH4 -> 0 | AQ15: ='QC Deviation Record Hall 3'!BP4 -> 0 | AR15: ='QC Deviation Record Hall 3'!BX4 -> 0
C16: مدى الوزن | S16: مدى الوزن | AH16: مدى الوزن
C17: متوسط الوزن | D17: =IFERROR(AVERAGE('QC Record Production Hall 1'!L9:L11),"") | E17: =IFERROR(AVERAGE('QC Record Production Hall 1'!Z9:Z11),"") | F17: =IFERROR(AVERAGE('QC Record Production Hall 1'!AN9:AN11),"") | G17: =IFERROR(AVERAGE('QC Record Production Hall 1'!BB9:BB11),"") | H17: =IFERROR(AVERAGE('QC Record Production Hall 1'!J33:J35),"") | I17: =IFERROR(AVERAGE('QC Record Production Hall 1'!V33:V35),"") | J17: =IFERROR(AVERAGE('QC Record Production Hall 1'!AN33:AN35),"") | K17: =IFERROR(AVERAGE('QC Record Production Hall 1'!BB33:BB35),"") | L17: =IFERROR(AVERAGE('QC Record Production Hall 1'!J57:J59),"") | M17: =IFERROR(AVERAGE('QC Record Production Hall 1'!W57:W59),"") | N17: =IFERROR(AVERAGE('QC Record Production Hall 1'!AK57:AK59),"") | O17: =IFERROR(AVERAGE('QC Record Production Hall 1'!AX57:AX59),"") | S17: متوسط الوزن | T17: =IFERROR(AVERAGE('QC Record Production Hall 2'!J9:J11),"") | U17: =IFERROR(AVERAGE('QC Record Production Hall 2'!V9:V11),"") | V17: =IFERROR(AVERAGE('QC Record Production Hall 2'!AG9:AG11),"") | W17: =IFERROR(AVERAGE('QC Record Production Hall 2'!AR9:AR11),"") | X17: =IFERROR(AVERAGE('QC Record Production Hall 2'!L33:L35),"") | Y17: =IFERROR(AVERAGE('QC Record Production Hall 2'!AD33:AD35),"") | Z17: =IFERROR(AVERAGE('QC Record Production Hall 2'!BC9:BC11),"") | AA17: =IFERROR(AVERAGE('QC Record Production Hall 2'!BN9:BN11),"") | AB17: =IFERROR(AVERAGE('QC Record Production Hall 2'!AR33:AR35),"") | AC17: =IFERROR(AVERAGE('QC Record Production Hall 2'!BC33:BC35),"") | AH17: متوسط الوزن | AI17: =IFERROR(AVERAGE('QC Record Production Hall 3'!J9:J11),"") | AJ17: =IFERROR(AVERAGE('QC Record Production Hall 3'!V9:V11),"") | AK17: =IFERROR(AVERAGE('QC Record Production Hall 3'!AG9:AG11),"") | AL17: =IFERROR(AVERAGE('QC Record Production Hall 3'!AR9:AR11),"") | AM17: =IFERROR(AVERAGE('QC Record Production Hall 3'!L33:L35),"") | AN17: =IFERROR(AVERAGE('QC Record Production Hall 3'!AD33:AD35),"") | AO17: =IFERROR(AVERAGE('QC Record Production Hall 3'!BC9:BC11),"") | AP17: =IFERROR(AVERAGE('QC Record Production Hall 3'!BN9:BN11),"") | AQ17: =IFERROR(AVERAGE('QC Record Production Hall 3'!AR33:AR35),"") | AR17: =IFERROR(AVERAGE('QC Record Production Hall 3'!BC33:BC35),"")
A18: الإثنين | C18: اسم المنتج | D18: ='QC Deviation Record Hall 1 '!E5 -> 0 | E18: ='QC Deviation Record Hall 1 '!M5 -> 0 | F18: ='QC Deviation Record Hall 1 '!U5 -> 0 | G18: ='QC Deviation Record Hall 1 '!AC5 -> 0 | H18: ='QC Deviation Record Hall 1 '!AK5 -> 0 | I18: ='QC Deviation Record Hall 1 '!AS5 -> 0 | J18: ='QC Deviation Record Hall 1 '!BA5 -> 0 | K18: ='QC Deviation Record Hall 1 '!BI5 -> 0 | L18: ='QC Deviation Record Hall 1 '!BQ5 -> 0 | M18: ='QC Deviation Record Hall 1 '!BY5 -> 0 | N18: ='QC Deviation Record Hall 1 '!CG5 -> 0 | O18: ='QC Deviation Record Hall 1 '!CO5 -> 0 | Q18: الإثنين | S18: اسم المنتج | T18: ='QC Deviation Record Hall 2'!E4 -> 0 | U18: ='QC Deviation Record Hall 2'!M4 -> 0 | V18: ='QC Deviation Record Hall 2'!U4 -> 0 | W18: ='QC Deviation Record Hall 2'!AC4 -> 0 | X18: ='QC Deviation Record Hall 2'!AK4 -> 0 | Y18: ='QC Deviation Record Hall 2'!AS4 -> 0 | Z18: ='QC Deviation Record Hall 2'!BA4 -> 0 | AA18: ='QC Deviation Record Hall 2'!BI4 -> 0 | AB18: ='QC Deviation Record Hall 2'!BQ4 -> 0 | AC18: ='QC Deviation Record Hall 2'!BY4 -> 0 | AF18: الإثنين | AH18: اسم المنتج | AI18: ='QC Deviation Record Hall 3'!E4 -> 0 | AJ18: ='QC Deviation Record Hall 3'!M4 -> 0 | AK18: ='QC Deviation Record Hall 3'!U4 -> 0 | AL18: ='QC Deviation Record Hall 3'!AC4 -> 0 | AM18: ='QC Deviation Record Hall 3'!AK4 -> 0 | AN18: ='QC Deviation Record Hall 3'!AS4 -> 0 | AO18: ='QC Deviation Record Hall 3'!BA4 -> 0 | AP18: ='QC Deviation Record Hall 3'!BI4 -> 0 | AQ18: ='QC Deviation Record Hall 3'!BQ4 -> 0 | AR18: ='QC Deviation Record Hall 3'!BY4 -> 0
C19: مدى الوزن | S19: مدى الوزن | AH19: مدى الوزن
C20: متوسط الوزن | D20: =IFERROR(AVERAGE('QC Record Production Hall 1'!L12:L14),"") | E20: =IFERROR(AVERAGE('QC Record Production Hall 1'!Z12:Z14),"") | F20: =IFERROR(AVERAGE('QC Record Production Hall 1'!AN12:AN14),"") | G20: =IFERROR(AVERAGE('QC Record Production Hall 1'!BB12:BB14),"") | H20: =IFERROR(AVERAGE('QC Record Production Hall 1'!J36:J38),"") | I20: =IFERROR(AVERAGE('QC Record Production Hall 1'!V36:V38),"") | J20: =IFERROR(AVERAGE('QC Record Production Hall 1'!AN36:AN38),"") | K20: =IFERROR(AVERAGE('QC Record Production Hall 1'!BB36:BB38),"") | L20: =IFERROR(AVERAGE('QC Record Production Hall 1'!J60:J62),"") | M20: =IFERROR(AVERAGE('QC Record Production Hall 1'!W60:W62),"") | N20: =IFERROR(AVERAGE('QC Record Production Hall 1'!AK60:AK62),"") | O20: =IFERROR(AVERAGE('QC Record Production Hall 1'!AX60:AX62),"") | S20: متوسط الوزن | T20: =IFERROR(AVERAGE('QC Record Production Hall 2'!J12:J14),"") | U20: =IFERROR(AVERAGE('QC Record Production Hall 2'!V12:V14),"") | V20: =IFERROR(AVERAGE('QC Record Production Hall 2'!AG12:AG14),"") | W20: =IFERROR(AVERAGE('QC Record Production Hall 2'!AR12:AR14),) -> 0 | X20: =IFERROR(AVERAGE('QC Record Production Hall 2'!L36:L38),"") | Y20: =IFERROR(AVERAGE('QC Record Production Hall 2'!AD36:AD38),"") | Z20: =IFERROR(AVERAGE('QC Record Production Hall 2'!BC12:BC14),"") | AA20: =IFERROR(AVERAGE('QC Record Production Hall 2'!BN12:BN14),"") | AB20: =IFERROR(AVERAGE('QC Record Production Hall 2'!AR36:AR38),"") | AC20: =IFERROR(AVERAGE('QC Record Production Hall 2'!BC36:BC38),"") | AH20: متوسط الوزن | AI20: =IFERROR(AVERAGE('QC Record Production Hall 3'!J12:J14),"") | AJ20: =IFERROR(AVERAGE('QC Record Production Hall 3'!V12:V14),"") | AK20: =IFERROR(AVERAGE('QC Record Production Hall 3'!AG12:AG14),"") | AL20: =IFERROR(AVERAGE('QC Record Production Hall 3'!AR12:AR14),) -> 0 | AM20: =IFERROR(AVERAGE('QC Record Production Hall 3'!L36:L38),"") | AN20: =IFERROR(AVERAGE('QC Record Production Hall 3'!AD36:AD38),"") | AO20: =IFERROR(AVERAGE('QC Record Production Hall 3'!BC12:BC14),"") | AP20: =IFERROR(AVERAGE('QC Record Production Hall 3'!BN12:BN14),"") | AQ20: =IFERROR(AVERAGE('QC Record Production Hall 3'!AR36:AR38),"") | AR20: =IFERROR(AVERAGE('QC Record Production Hall 3'!BC36:BC38),"")
A21: الثلاثاء | C21: اسم المنتج | D21: ='QC Deviation Record Hall 1 '!F5 -> 0 | E21: ='QC Deviation Record Hall 1 '!N5 -> 0 | F21: ='QC Deviation Record Hall 1 '!V5 -> 0 | G21: ='QC Deviation Record Hall 1 '!AD5 -> 0 | H21: ='QC Deviation Record Hall 1 '!AL5 -> 0 | I21: ='QC Deviation Record Hall 1 '!AT5 -> 0 | J21: ='QC Deviation Record Hall 1 '!BB5 -> 0 | K21: ='QC Deviation Record Hall 1 '!BJ5 -> 0 | L21: ='QC Deviation Record Hall 1 '!BR5 -> 0 | M21: ='QC Deviation Record Hall 1 '!BZ5 -> 0 | N21: ='QC Deviation Record Hall 1 '!CH5 -> 0 | O21: ='QC Deviation Record Hall 1 '!CP5 -> 0 | Q21: الثلاثاء | S21: اسم المنتج | T21: ='QC Deviation Record Hall 2'!F4 -> 0 | U21: ='QC Deviation Record Hall 2'!N4 -> 0 | V21: ='QC Deviation Record Hall 2'!V4 -> 0 | W21: ='QC Deviation Record Hall 2'!AD4 -> 0 | X21: ='QC Deviation Record Hall 2'!AL4 -> 0 | Y21: ='QC Deviation Record Hall 2'!AT4 -> 0 | Z21: ='QC Deviation Record Hall 2'!BB4 -> 0 | AA21: ='QC Deviation Record Hall 2'!BJ4 -> 0 | AB21: ='QC Deviation Record Hall 2'!BR4 -> 0 | AC21: ='QC Deviation Record Hall 2'!BZ4 -> 0 | AF21: الثلاثاء | AH21: اسم المنتج | AI21: ='QC Deviation Record Hall 3'!F4 -> 0 | AJ21: ='QC Deviation Record Hall 3'!N4 -> 0 | AK21: ='QC Deviation Record Hall 3'!V4 -> 0 | AL21: ='QC Deviation Record Hall 3'!AD4 -> 0 | AM21: ='QC Deviation Record Hall 3'!AL4 -> 0 | AN21: ='QC Deviation Record Hall 3'!AT4 -> 0 | AO21: ='QC Deviation Record Hall 3'!BB4 -> 0 | AP21: ='QC Deviation Record Hall 3'!BJ4 -> 0 | AQ21: ='QC Deviation Record Hall 3'!BR4 -> 0 | AR21: ='QC Deviation Record Hall 3'!BZ4 -> 0
C22: مدى الوزن | S22: مدى الوزن | AH22: مدى الوزن
C23: متوسط الوزن | D23: =IFERROR(AVERAGE('QC Record Production Hall 1'!L15:L17),"") | E23: =IFERROR(AVERAGE('QC Record Production Hall 1'!Z15:Z17),"") | F23: =IFERROR(AVERAGE('QC Record Production Hall 1'!AN15:AN17),"") | G23: =IFERROR(AVERAGE('QC Record Production Hall 1'!BB15:BB17),"") | H23: =IFERROR(AVERAGE('QC Record Production Hall 1'!J39:J41),"") | I23: =IFERROR(AVERAGE('QC Record Production Hall 1'!V39:V41),"") | J23: =IFERROR(AVERAGE('QC Record Production Hall 1'!AN39:AN41),"") | K23: =IFERROR(AVERAGE('QC Record Production Hall 1'!BB39:BB41),"") | L23: =IFERROR(AVERAGE('QC Record Production Hall 1'!J63:J65),"") | M23: =IFERROR(AVERAGE('QC Record Production Hall 1'!W63:W65),"") | N23: =IFERROR(AVERAGEA('QC Record Production Hall 1'!AK63:AK65),"") | O23: =IFERROR(AVERAGE('QC Record Production Hall 1'!AX63:AX65),"") | S23: متوسط الوزن | T23: =IFERROR(AVERAGE('QC Record Production Hall 2'!J15:J17),"") | U23: =IFERROR(AVERAGE('QC Record Production Hall 2'!V15:V17),"") | V23: =IFERROR(AVERAGE('QC Record Production Hall 2'!AG15:AG17),"") | W23: =IFERROR(AVERAGE('QC Record Production Hall 2'!AR15:AR17),"") | X23: =IFERROR(AVERAGE('QC Record Production Hall 2'!L39:L41),"") | Y23: =IFERROR(AVERAGE('QC Record Production Hall 2'!AD39:AD41),"") | Z23: =IFERROR(AVERAGE('QC Record Production Hall 2'!BC15:BC17),"") | AA23: =IFERROR(AVERAGE('QC Record Production Hall 2'!BN15:BN17),"") | AB23: =IFERROR(AVERAGE('QC Record Production Hall 2'!AR39:AR41),"") | AC23: =IFERROR(AVERAGE('QC Record Production Hall 2'!BC39:BC41),"") | AH23: متوسط الوزن | AI23: =IFERROR(AVERAGE('QC Record Production Hall 3'!J15:J17),"") | AJ23: =IFERROR(AVERAGE('QC Record Production Hall 3'!V15:V17),"") | AK23: =IFERROR(AVERAGE('QC Record Production Hall 3'!AG15:AG17),"") | AL23: =IFERROR(AVERAGE('QC Record Production Hall 3'!AR15:AR17),"") | AM23: =IFERROR(AVERAGE('QC Record Production Hall 3'!L39:L41),"") | AN23: =IFERROR(AVERAGE('QC Record Production Hall 3'!AD39:AD41),"") | AO23: =IFERROR(AVERAGE('QC Record Production Hall 3'!BC15:BC17),"") | AP23: =IFERROR(AVERAGE('QC Record Production Hall 3'!BN15:BN17),"") | AQ23: =IFERROR(AVERAGE('QC Record Production Hall 3'!AR39:AR41),"") | AR23: =IFERROR(AVERAGE('QC Record Production Hall 3'!BC39:BC41),"")
A24: الأربعاء | C24: اسم المنتج | D24: ='QC Deviation Record Hall 1 '!G5 -> 0 | E24: ='QC Deviation Record Hall 1 '!O5 -> 0 | F24: ='QC Deviation Record Hall 1 '!W5 -> 0 | G24: ='QC Deviation Record Hall 1 '!AE5 -> 0 | H24: ='QC Deviation Record Hall 1 '!AM5 -> 0 | I24: ='QC Deviation Record Hall 1 '!AU5 -> 0 | J24: ='QC Deviation Record Hall 1 '!BC5 -> 0 | K24: ='QC Deviation Record Hall 1 '!BK5 -> 0 | L24: ='QC Deviation Record Hall 1 '!BS5 -> 0 | M24: ='QC Deviation Record Hall 1 '!CA5 -> 0 | N24: ='QC Deviation Record Hall 1 '!CI5 -> 0 | O24: ='QC Deviation Record Hall 1 '!CQ5 -> 0 | Q24: الأربعاء | S24: اسم المنتج | T24: ='QC Deviation Record Hall 2'!G4 -> 0 | U24: ='QC Deviation Record Hall 2'!O4 -> 0 | V24: ='QC Deviation Record Hall 2'!W4 -> 0 | W24: ='QC Deviation Record Hall 2'!AE4 -> 0 | X24: ='QC Deviation Record Hall 2'!AM4 -> 0 | Y24: ='QC Deviation Record Hall 2'!AU4 -> 0 | Z24: ='QC Deviation Record Hall 2'!BC4 -> 0 | AA24: ='QC Deviation Record Hall 2'!BK4 -> 0 | AB24: ='QC Deviation Record Hall 2'!BS4 -> 0 | AC24: ='QC Deviation Record Hall 2'!CA4 -> 0 | AF24: الأربعاء | AH24: اسم المنتج | AI24: ='QC Deviation Record Hall 3'!G4 -> 0 | AJ24: ='QC Deviation Record Hall 3'!O4 -> 0 | AK24: ='QC Deviation Record Hall 3'!W4 -> 0 | AL24: ='QC Deviation Record Hall 3'!AE4 -> 0 | AM24: ='QC Deviation Record Hall 3'!AM4 -> 0 | AN24: ='QC Deviation Record Hall 3'!AU4 -> 0 | AO24: ='QC Deviation Record Hall 3'!BC4 -> 0 | AP24: ='QC Deviation Record Hall 3'!BK4 -> 0 | AQ24: ='QC Deviation Record Hall 3'!BS4 -> 0 | AR24: ='QC Deviation Record Hall 3'!CA4 -> 0
C25: مدى الوزن | S25: مدى الوزن | AH25: مدى الوزن
C26: متوسط الوزن | D26: =IFERROR(AVERAGE('QC Record Production Hall 1'!L18:L20),"") | E26: =IFERROR(AVERAGE('QC Record Production Hall 1'!Z18:Z20),"") | F26: =IFERROR(AVERAGE('QC Record Production Hall 1'!AN18:AN20),"") | G26: =IFERROR(AVERAGE('QC Record Production Hall 1'!BB18:BB20),"") | H26: =IFERROR(AVERAGE('QC Record Production Hall 1'!J42:J44),"") | I26: =IFERROR(AVERAGE('QC Record Production Hall 1'!V42:V44),"") | J26: =IFERROR(AVERAGE('QC Record Production Hall 1'!AN42:AN44),"") | K26: =IFERROR(AVERAGE('QC Record Production Hall 1'!BB42:BB44),"") | L26: =IFERROR(AVERAGE('QC Record Production Hall 1'!J66:J68),"") | M26: =IFERROR(AVERAGE('QC Record Production Hall 1'!W66:W68),"") | N26: =IFERROR(AVERAGE('QC Record Production Hall 1'!AK66:AK68),"") | O26: =IFERROR(AVERAGE('QC Record Production Hall 1'!AX66:AX68),"") | S26: متوسط الوزن | T26: =IFERROR(AVERAGE('QC Record Production Hall 2'!J18:J20),"") | U26: =IFERROR(AVERAGE('QC Record Production Hall 2'!V18:V20),"") | V26: =IFERROR(AVERAGE('QC Record Production Hall 2'!AG18:AG20),"") | W26: =IFERROR(AVERAGE('QC Record Production Hall 2'!AR18:AR20),"") | X26: =IFERROR(AVERAGE('QC Record Production Hall 2'!L42:L44),"") | Y26: =IFERROR(AVERAGE('QC Record Production Hall 2'!AD42:AD44),"") | Z26: =IFERROR(AVERAGE('QC Record Production Hall 2'!BC18:BC20),"") | AA26: =IFERROR(AVERAGE('QC Record Production Hall 2'!BN18:BN20),"") | AB26: =IFERROR(AVERAGE('QC Record Production Hall 2'!AR42:AR44),"") | AC26: =IFERROR(AVERAGE('QC Record Production Hall 2'!BC42:BC44),"") | AH26: متوسط الوزن | AI26: =IFERROR(AVERAGE('QC Record Production Hall 3'!J18:J20),"") | AJ26: =IFERROR(AVERAGE('QC Record Production Hall 3'!V18:V20),"") | AK26: =IFERROR(AVERAGE('QC Record Production Hall 3'!AG18:AG20),"") | AL26: =IFERROR(AVERAGE('QC Record Production Hall 3'!AR18:AR20),"") | AM26: =IFERROR(AVERAGE('QC Record Production Hall 3'!L42:L44),"") | AN26: =IFERROR(AVERAGE('QC Record Production Hall 3'!AD42:AD44),"") | AO26: =IFERROR(AVERAGE('QC Record Production Hall 3'!BC18:BC20),"") | AP26: =IFERROR(AVERAGE('QC Record Production Hall 3'!BN18:BN20),"") | AQ26: =IFERROR(AVERAGE('QC Record Production Hall 3'!AR42:AR44),"") | AR26: =IFERROR(AVERAGE('QC Record Production Hall 3'!BC42:BC44),"")
A27: الخميس | C27: اسم المنتج | D27: ='QC Deviation Record Hall 1 '!H5 -> 0 | E27: ='QC Deviation Record Hall 1 '!P5 -> 0 | F27: ='QC Deviation Record Hall 1 '!X5 -> 0 | G27: ='QC Deviation Record Hall 1 '!AF5 -> 0 | H27: ='QC Deviation Record Hall 1 '!AN5 -> 0 | I27: ='QC Deviation Record Hall 1 '!AV5 -> 0 | J27: ='QC Deviation Record Hall 1 '!BD5 -> 0 | K27: ='QC Deviation Record Hall 1 '!BL5 -> 0 | L27: ='QC Deviation Record Hall 1 '!BT5 -> 0 | M27: ='QC Deviation Record Hall 1 '!CB5 -> 0 | N27: ='QC Deviation Record Hall 1 '!CJ5 -> 0 | O27: ='QC Deviation Record Hall 1 '!CR5 -> 0 | Q27: الخميس | S27: اسم المنتج | T27: ='QC Deviation Record Hall 2'!H4 -> 0 | U27: ='QC Deviation Record Hall 2'!P4 -> 0 | V27: ='QC Deviation Record Hall 2'!X4 -> 0 | W27: ='QC Deviation Record Hall 2'!AF4 -> 0 | X27: ='QC Deviation Record Hall 2'!AN4 -> 0 | Y27: ='QC Deviation Record Hall 2'!AV4 -> 0 | Z27: ='QC Deviation Record Hall 2'!BD4 -> 0 | AA27: ='QC Deviation Record Hall 2'!BL4 -> 0 | AB27: ='QC Deviation Record Hall 2'!BT4 -> 0 | AC27: ='QC Deviation Record Hall 2'!CB4 -> 0 | AF27: الخميس | AH27: اسم المنتج | AI27: ='QC Deviation Record Hall 3'!H4 -> 0 | AJ27: ='QC Deviation Record Hall 3'!P4 -> 0 | AK27: ='QC Deviation Record Hall 3'!X4 -> 0 | AL27: ='QC Deviation Record Hall 3'!AF4 -> 0 | AM27: ='QC Deviation Record Hall 3'!AN4 -> 0 | AN27: ='QC Deviation Record Hall 3'!AV4 -> 0 | AO27: ='QC Deviation Record Hall 3'!BD4 -> 0 | AP27: ='QC Deviation Record Hall 3'!BL4 -> 0 | AQ27: ='QC Deviation Record Hall 3'!BT4 -> 0 | AR27: ='QC Deviation Record Hall 3'!CB4 -> 0
C28: مدى الوزن | S28: مدى الوزن | AH28: مدى الوزن
C29: متوسط الوزن | D29: =IFERROR(AVERAGE('QC Record Production Hall 1'!L21:L23),"") | E29: =IFERROR(AVERAGE('QC Record Production Hall 1'!Z21:Z23),"") | F29: =IFERROR(AVERAGE('QC Record Production Hall 1'!AN21:AN23),"") | G29: =IFERROR(AVERAGE('QC Record Production Hall 1'!BB21:BB23),"") | H29: =IFERROR(AVERAGE('QC Record Production Hall 1'!J45:J47),"") | I29: =IFERROR(AVERAGE('QC Record Production Hall 1'!V45:V47),"") | J29: =IFERROR(AVERAGE('QC Record Production Hall 1'!AN45:AN47),"") | K29: =IFERROR(AVERAGE('QC Record Production Hall 1'!BB45:BB47),"") | L29: =IFERROR(AVERAGE('QC Record Production Hall 1'!J69:J71),"") | M29: =IFERROR(AVERAGE('QC Record Production Hall 1'!W69:W71),"") | N29: =IFERROR(AVERAGE('QC Record Production Hall 1'!AK69:AK71),"") | O29: =IFERROR(AVERAGE('QC Record Production Hall 1'!AX69:AX71),"") | S29: متوسط الوزن | T29: =IFERROR(AVERAGE('QC Record Production Hall 2'!J21:J23),"") | U29: =IFERROR(AVERAGE('QC Record Production Hall 2'!V21:V23),"") | V29: =IFERROR(AVERAGE('QC Record Production Hall 2'!AG21:AG23),"") | W29: =IFERROR(AVERAGE('QC Record Production Hall 2'!AR21:AR23),"") | X29: =IFERROR(AVERAGE('QC Record Production Hall 2'!L45:L47),"") | Y29: =IFERROR(AVERAGE('QC Record Production Hall 2'!AD45:AD47),"") | Z29: =IFERROR(AVERAGE('QC Record Production Hall 2'!BC21:BC23),"") | AA29: =IFERROR(AVERAGE('QC Record Production Hall 2'!BN21:BN23),"") | AB29: =IFERROR(AVERAGE('QC Record Production Hall 2'!AR45:AR47),"") | AC29: =IFERROR(AVERAGE('QC Record Production Hall 2'!BC45:BC47),"") | AH29: متوسط الوزن | AI29: =IFERROR(AVERAGE('QC Record Production Hall 3'!J21:J23),"") | AJ29: =IFERROR(AVERAGE('QC Record Production Hall 3'!V21:V23),"") | AK29: =IFERROR(AVERAGE('QC Record Production Hall 3'!AG21:AG23),"") | AL29: =IFERROR(AVERAGE('QC Record Production Hall 3'!AR21:AR23),"") | AM29: =IFERROR(AVERAGE('QC Record Production Hall 3'!L45:L47),"") | AN29: =IFERROR(AVERAGE('QC Record Production Hall 3'!AD45:AD47),"") | AO29: =IFERROR(AVERAGE('QC Record Production Hall 3'!BC21:BC23),"") | AP29: =IFERROR(AVERAGE('QC Record Production Hall 3'!BN21:BN23),"") | AQ29: =IFERROR(AVERAGE('QC Record Production Hall 3'!AR45:AR47),"") | AR29: =IFERROR(AVERAGE('QC Record Production Hall 3'!BC45:BC47),"")
A30: الجمعة | C30: اسم المنتج | D30: ='QC Deviation Record Hall 1 '!I5 -> 0 | E30: ='QC Deviation Record Hall 1 '!Q5 -> 0 | F30: ='QC Deviation Record Hall 1 '!Y5 -> 0 | G30: ='QC Deviation Record Hall 1 '!AG5 -> 0 | H30: ='QC Deviation Record Hall 1 '!AO5 -> 0 | I30: ='QC Deviation Record Hall 1 '!AW5 -> 0 | J30: ='QC Deviation Record Hall 1 '!BE5 -> 0 | K30: ='QC Deviation Record Hall 1 '!BM5 -> 0 | L30: ='QC Deviation Record Hall 1 '!BU5 -> 0 | M30: ='QC Deviation Record Hall 1 '!CC5 -> 0 | N30: ='QC Deviation Record Hall 1 '!CK5 -> 0 | O30: ='QC Deviation Record Hall 1 '!CS5 -> 0 | Q30: الجمعة | S30: اسم المنتج | T30: ='QC Deviation Record Hall 2'!I4 -> 0 | U30: ='QC Deviation Record Hall 2'!Q4 -> 0 | V30: ='QC Deviation Record Hall 2'!Y4 -> 0 | W30: ='QC Deviation Record Hall 2'!AG4 -> 0 | X30: ='QC Deviation Record Hall 2'!AO4 -> 0 | Y30: ='QC Deviation Record Hall 2'!AW4 -> 0 | Z30: ='QC Deviation Record Hall 2'!BE4 -> 0 | AA30: ='QC Deviation Record Hall 2'!BM4 -> 0 | AB30: ='QC Deviation Record Hall 2'!BU4 -> 0 | AC30: ='QC Deviation Record Hall 2'!CC4 -> 0 | AF30: الجمعة | AH30: اسم المنتج | AI30: ='QC Deviation Record Hall 3'!I4 -> 0 | AJ30: ='QC Deviation Record Hall 3'!Q4 -> 0 | AK30: ='QC Deviation Record Hall 3'!Y4 -> 0 | AL30: ='QC Deviation Record Hall 3'!AG4 -> 0 | AM30: ='QC Deviation Record Hall 3'!AO4 -> 0 | AN30: ='QC Deviation Record Hall 3'!AW4 -> 0 | AO30: ='QC Deviation Record Hall 3'!BE4 -> 0 | AP30: ='QC Deviation Record Hall 3'!BM4 -> 0 | AQ30: ='QC Deviation Record Hall 3'!BU4 -> 0 | AR30: ='QC Deviation Record Hall 3'!CC4 -> 0
C31: مدى الوزن | S31: مدى الوزن | AH31: مدى الوزن
C32: متوسط الوزن | D32: =IFERROR(AVERAGE('QC Record Production Hall 1'!L3:L5),"") | E32: =IFERROR(AVERAGE('QC Record Production Hall 1'!Z3:Z5),"") | F32: =IFERROR(AVERAGE('QC Record Production Hall 1'!AN3:AN5),"") | G32: =IFERROR(AVERAGE('QC Record Production Hall 1'!BB3:BB5),"") | H32: =IFERROR(AVERAGE('QC Record Production Hall 1'!J27:J29),"") | I32: =IFERROR(AVERAGE('QC Record Production Hall 1'!V27:V29),"") | J32: =IFERROR(AVERAGE('QC Record Production Hall 1'!AN27:AN29),"") | K32: =IFERROR(AVERAGE('QC Record Production Hall 1'!BB27:BB29),"") | L32: =IFERROR(AVERAGE('QC Record Production Hall 1'!J51:J53),"") | M32: =IFERROR(AVERAGE('QC Record Production Hall 1'!W51:W53),"") | N32: =IFERROR(AVERAGE('QC Record Production Hall 1'!AK51:AK53),"") | O32: =IFERROR(AVERAGE('QC Record Production Hall 1'!AX51:AX53),"") | S32: متوسط الوزن | T32: =IFERROR(AVERAGE('QC Record Production Hall 2'!J3:J5),"") | U32: =IFERROR(AVERAGE('QC Record Production Hall 2'!V3:V5),"") | V32: =IFERROR(AVERAGE('QC Record Production Hall 2'!AG3:AG5),"") | W32: =IFERROR(AVERAGE('QC Record Production Hall 2'!AR3:AR5),"") | X32: =IFERROR(AVERAGE('QC Record Production Hall 2'!L27:L29),"") | Y32: =IFERROR(AVERAGE('QC Record Production Hall 2'!AD27:AD29),"") | Z32: =IFERROR(AVERAGE('QC Record Production Hall 2'!BC3:BC5),"") | AA32: =IFERROR(AVERAGE('QC Record Production Hall 2'!BN3:BN5),"") | AB32: =IFERROR(AVERAGE('QC Record Production Hall 2'!AR27:AR29),"") | AC32: =IFERROR(AVERAGE('QC Record Production Hall 2'!BC27:BC29),"") | AH32: متوسط الوزن | AI32: =IFERROR(AVERAGE('QC Record Production Hall 3'!J3:J5),"") | AJ32: =IFERROR(AVERAGE('QC Record Production Hall 3'!V3:V5),"") | AK32: =IFERROR(AVERAGE('QC Record Production Hall 3'!AG3:AG5),"") | AL32: =IFERROR(AVERAGE('QC Record Production Hall 3'!AR3:AR5),"") | AM32: =IFERROR(AVERAGE('QC Record Production Hall 3'!L27:L29),"") | AN32: =IFERROR(AVERAGE('QC Record Production Hall 3'!AD27:AD29),"") | AO32: =IFERROR(AVERAGE('QC Record Production Hall 3'!BC3:BC5),"") | AP32: =IFERROR(AVERAGE('QC Record Production Hall 3'!BN3:BN5),"") | AQ32: =IFERROR(AVERAGE('QC Record Production Hall 3'!AR27:AR29),"") | AR32: =IFERROR(AVERAGE('QC Record Production Hall 3'!BC27:BC29),"")
A33: Code | B33: Defect العيب | C33: Tolerance | D33: M1-1 | E33: M2-1 | F33: M3-2 | G33: M4-2 | H33: M5-3 | I33: M6-3 | J33: M7-3 | K33: M8-4 | L33: M9-5 | M33: M10-6 | N33: M10-6 | O33: M18-13 | Q33: Code | R33: Defect العيب | S33: Tolerance | T33: M11-7 | U33: M12-7 | V33: M13-8 | W33: M13-8 | X33: M14-9 | Y33: M15-10 | Z33: M16-11 | AA33: M16-11 | AB33: M17-12 | AC33: M17-12 | AF33: Code | AG33: Defect العيب | AH33: Tolerance | AI33: M11-7 | AJ33: M12-7 | AK33: M13-8 | AL33: M13-8 | AM33: M14-9 | AN33: M15-10 | AO33: M16-11 | AP33: M16-11 | AQ33: M17-12 | AR33: M17-12
A34: {=INDEX('QC Deviation Record Hall 1 '!$A$120:$A$221,MATCH(Table7[[#This Row],[Defect العيب]],'QC Deviation Record Hall 1 '!$B$120:$B$221,0))} -> AD01 | B34: {=INDEX('QC Deviation Record Hall 1 '!$B$120:$B$221,MATCH(LARGE('QC Deviation Record Hall 1 '!$O$120:$O$221-ROW('QC Deviation Record Hall 1 '!$O$120:$O$221)/10000000,ROW(A1)),'QC Deviation Record Hall 1 '!$O$120:$O$221-ROW('QC Deviation Record Hall 1 '!$O$120:$O$221)/10000000,0))} -> تكتل الإضافات في جزء واحد | D34: {=INDEX('QC Deviation Record Hall 1 '!$C$120:$C$221,MATCH(Table7[[#This Row],[Defect العيب]],'QC Deviation Record Hall 1 '!$B$120:$B$221,0))} | E34: {=INDEX('QC Deviation Record Hall 1 '!$D$120:$D$221,MATCH(Table7[[#This Row],[Defect العيب]],'QC Deviation Record Hall 1 '!$B$120:$B$221,0))} | F34: {=INDEX('QC Deviation Record Hall 1 '!$E$120:$E$221,MATCH(Table7[[#This Row],[Defect العيب]],'QC Deviation Record Hall 1 '!$B$120:$B$221,0))} | G34: {=INDEX('QC Deviation Record Hall 1 '!$F$120:$F$221,MATCH(Table7[[#This Row],[Defect العيب]],'QC Deviation Record Hall 1 '!$B$120:$B$221,0))} | H34: {=INDEX('QC Deviation Record Hall 1 '!$G$120:$G$221,MATCH(Table7[[#This Row],[Defect العيب]],'QC Deviation Record Hall 1 '!$B$120:$B$221,0))} | I34: {=INDEX('QC Deviation Record Hall 1 '!$H$120:$H$221,MATCH(Table7[[#This Row],[Defect العيب]],'QC Deviation Record Hall 1 '!$B$120:$B$221,0))} | J34: {=INDEX('QC Deviation Record Hall 1 '!$I$120:$I$221,MATCH(Table7[[#This Row],[Defect العيب]],'QC Deviation Record Hall 1 '!$B$120:$B$221,0))} | K34: {=INDEX('QC Deviation Record Hall 1 '!$J$120:$J$221,MATCH(Table7[[#This Row],[Defect العيب]],'QC Deviation Record Hall 1 '!$B$120:$B$221,0))} | L34: {=INDEX('QC Deviation Record Hall 1 '!$K$120:$K$221,MATCH(Table7[[#This Row],[Defect العيب]],'QC Deviation Record Hall 1 '!$B$120:$B$221,0))} | M34: {=INDEX('QC Deviation Record Hall 1 '!$L$120:$L$221,MATCH(Table7[[#This Row],[Defect العيب]],'QC Deviation Record Hall 1 '!$B$120:$B$221,0))} | N34: {=INDEX('QC Deviation Record Hall 1 '!$M$120:$M$221,MATCH(Table7[[#This Row],[Defect العيب]],'QC Deviation Record Hall 1 '!$B$120:$B$221,0))} | O34: {=INDEX('QC Deviation Record Hall 1 '!$N$120:$N$221,MATCH(Table7[[#This Row],[Defect العيب]],'QC Deviation Record Hall 1 '!$B$120:$B$221,0))} | Q34: {=INDEX('QC Deviation Record Hall 2'!$A$119:$A$220,MATCH(Table11[[#This Row],[Defect العيب]],'QC Deviation Record Hall 2'!$B$119:$B$220,0))} -> AD01 | R34: {=INDEX('QC Deviation Record Hall 2'!$B$119:$B$220,MATCH(LARGE('QC Deviation Record Hall 2'!$M$119:$M$220-ROW('QC Deviation Record Hall 2'!$M$119:$M$220)/10000000,ROW(A1)),'QC Deviation Record Hall 2'!$M$119:$M$220-ROW('QC Deviation Record Hall 2'!$M$119:$M$220)/10000000,0))} -> تكتل الإضافات في جزء واحد | T34: {=INDEX('QC Deviation Record Hall 2'!$C$119:$C$220,MATCH(Table11[[#This Row],[Defect العيب]],'QC Deviation Record Hall 2'!$B$119:$B$220,0))} | U34: {=INDEX('QC Deviation Record Hall 2'!$D$119:$D$220,MATCH(Table11[[#This Row],[Defect العيب]],'QC Deviation Record Hall 2'!$B$119:$B$220,0))} | V34: {=INDEX('QC Deviation Record Hall 2'!$E$119:$E$220,MATCH(Table11[[#This Row],[Defect العيب]],'QC Deviation Record Hall 2'!$B$119:$B$220,0))} | W34: {=INDEX('QC Deviation Record Hall 2'!$F$119:$F$220,MATCH(Table11[[#This Row],[Defect العيب]],'QC Deviation Record Hall 2'!$B$119:$B$220,0))} | X34: {=INDEX('QC Deviation Record Hall 2'!$G$119:$G$220,MATCH(Table11[[#This Row],[Defect العيب]],'QC Deviation Record Hall 2'!$B$119:$B$220,0))} | Y34: {=INDEX('QC Deviation Record Hall 2'!$H$119:$H$220,MATCH(Table11[[#This Row],[Defect العيب]],'QC Deviation Record Hall 2'!$B$119:$B$220,0))} | Z34: {=INDEX('QC Deviation Record Hall 2'!$I$119:$I$220,MATCH(Table11[[#This Row],[Defect العيب]],'QC Deviation Record Hall 2'!$B$119:$B$220,0))} | AA34: {=INDEX('QC Deviation Record Hall 2'!$J$119:$J$220,MATCH(Table11[[#This Row],[Defect العيب]],'QC Deviation Record Hall 2'!$B$119:$B$220,0))} | AB34: {=INDEX('QC Deviation Record Hall 2'!$K$119:$K$220,MATCH(Table11[[#This Row],[Defect العيب]],'QC Deviation Record Hall 2'!$B$119:$B$220,0))} | AC34: {=INDEX('QC Deviation Record Hall 2'!$L$119:$L$220,MATCH(Table11[[#This Row],[Defect العيب]],'QC Deviation Record Hall 2'!$B$119:$B$220,0))} | AF34: {=INDEX('QC Deviation Record Hall 3'!$A$119:$A$220,MATCH(Table111[[#This Row],[Defect العيب]],'QC Deviation Record Hall 3'!$B$119:$B$220,0))} -> AD01 | AG34: {=INDEX('QC Deviation Record Hall 3'!$B$119:$B$220,MATCH(LARGE('QC Deviation Record Hall 3'!$M$119:$M$220-ROW('QC Deviation Record Hall 3'!$M$119:$M$220)/10000000,ROW(A1)),'QC Deviation Record Hall 3'!$M$119:$M$220-ROW('QC Deviation Record Hall 3'!$M$119:$M$220)/10000000,0))} -> تكتل الإضافات في جزء واحد | AI34: {=INDEX('QC Deviation Record Hall 3'!$C$119:$C$220,MATCH(Table111[[#This Row],[Defect العيب]],'QC Deviation Record Hall 3'!$B$119:$B$220,0))} | AJ34: {=INDEX('QC Deviation Record Hall 3'!$D$119:$D$220,MATCH(Table111[[#This Row],[Defect العيب]],'QC Deviation Record Hall 3'!$B$119:$B$220,0))} | AK34: {=INDEX('QC Deviation Record Hall 3'!$E$119:$E$220,MATCH(Table111[[#This Row],[Defect العيب]],'QC Deviation Record Hall 3'!$B$119:$B$220,0))} | AL34: {=INDEX('QC Deviation Record Hall 3'!$F$119:$F$220,MATCH(Table111[[#This Row],[Defect العيب]],'QC Deviation Record Hall 3'!$B$119:$B$220,0))} | AM34: {=INDEX('QC Deviation Record Hall 3'!$G$119:$G$220,MATCH(Table111[[#This Row],[Defect العيب]],'QC Deviation Record Hall 3'!$B$119:$B$220,0))} | AN34: {=INDEX('QC Deviation Record Hall 3'!$H$119:$H$220,MATCH(Table111[[#This Row],[Defect العيب]],'QC Deviation Record Hall 3'!$B$119:$B$220,0))} | AO34: {=INDEX('QC Deviation Record Hall 3'!$I$119:$I$220,MATCH(Table111[[#This Row],[Defect العيب]],'QC Deviation Record Hall 3'!$B$119:$B$220,0))} | AP34: {=INDEX('QC Deviation Record Hall 3'!$J$119:$J$220,MATCH(Table111[[#This Row],[Defect العيب]],'QC Deviation Record Hall 3'!$B$119:$B$220,0))} | AQ34: {=INDEX('QC Deviation Record Hall 3'!$K$119:$K$220,MATCH(Table111[[#This Row],[Defect العيب]],'QC Deviation Record Hall 3'!$B$119:$B$220,0))} | AR34: {=INDEX('QC Deviation Record Hall 3'!$L$119:$L$220,MATCH(Table111[[#This Row],[Defect العيب]],'QC Deviation Record Hall 3'!$B$119:$B$220,0))}
A35: {=INDEX('QC Deviation Record Hall 1 '!$A$120:$A$221,MATCH(Table7[[#This Row],[Defect العيب]],'QC Deviation Record Hall 1 '!$B$120:$B$221,0))} -> AD02 | B35: {=INDEX('QC Deviation Record Hall 1 '!$B$120:$B$221,MATCH(LARGE('QC Deviation Record Hall 1 '!$O$120:$O$221-ROW('QC Deviation Record Hall 1 '!$O$120:$O$221)/10000000,ROW(A2)),'QC Deviation Record Hall 1 '!$O$120:$O$221-ROW('QC Deviation Record Hall 1 '!$O$120:$O$221)/10000000,0))} -> إضافات رطبة/مكسورة زيادة | D35: {=INDEX('QC Deviation Record Hall 1 '!$C$120:$C$221,MATCH(Table7[[#This Row],[Defect العيب]],'QC Deviation Record Hall 1 '!$B$120:$B$221,0))} | E35: {=INDEX('QC Deviation Record Hall 1 '!$D$120:$D$221,MATCH(Table7[[#This Row],[Defect العيب]],'QC Deviation Record Hall 1 '!$B$120:$B$221,0))} | F35: {=INDEX('QC Deviation Record Hall 1 '!$E$120:$E$221,MATCH(Table7[[#This Row],[Defect العيب]],'QC Deviation Record Hall 1 '!$B$120:$B$221,0))} | G35: {=INDEX('QC Deviation Record Hall 1 '!$F$120:$F$221,MATCH(Table7[[#This Row],[Defect العيب]],'QC Deviation Record Hall 1 '!$B$120:$B$221,0))} | H35: {=INDEX('QC Deviation Record Hall 1 '!$G$120:$G$221,MATCH(Table7[[#This Row],[Defect العيب]],'QC Deviation Record Hall 1 '!$B$120:$B$221,0))} | I35: {=INDEX('QC Deviation Record Hall 1 '!$H$120:$H$221,MATCH(Table7[[#This Row],[Defect العيب]],'QC Deviation Record Hall 1 '!$B$120:$B$221,0))} | J35: {=INDEX('QC Deviation Record Hall 1 '!$I$120:$I$221,MATCH(Table7[[#This Row],[Defect العيب]],'QC Deviation Record Hall 1 '!$B$120:$B$221,0))} | K35: {=INDEX('QC Deviation Record Hall 1 '!$J$120:$J$221,MATCH(Table7[[#This Row],[Defect العيب]],'QC Deviation Record Hall 1 '!$B$120:$B$221,0))} | L35: {=INDEX('QC Deviation Record Hall 1 '!$K$120:$K$221,MATCH(Table7[[#This Row],[Defect العيب]],'QC Deviation Record Hall 1 '!$B$120:$B$221,0))} | M35: {=INDEX('QC Deviation Record Hall 1 '!$L$120:$L$221,MATCH(Table7[[#This Row],[Defect العيب]],'QC Deviation Record Hall 1 '!$B$120:$B$221,0))} | N35: {=INDEX('QC Deviation Record Hall 1 '!$M$120:$M$221,MATCH(Table7[[#This Row],[Defect العيب]],'QC Deviation Record Hall 1 '!$B$120:$B$221,0))} | O35: {=INDEX('QC Deviation Record Hall 1 '!$N$120:$N$221,MATCH(Table7[[#This Row],[Defect العيب]],'QC Deviation Record Hall 1 '!$B$120:$B$221,0))} | Q35: {=INDEX('QC Deviation Record Hall 2'!$A$119:$A$220,MATCH(Table11[[#This Row],[Defect العيب]],'QC Deviation Record Hall 2'!$B$119:$B$220,0))} -> AD02 | R35: {=INDEX('QC Deviation Record Hall 2'!$B$119:$B$220,MATCH(LARGE('QC Deviation Record Hall 2'!$M$119:$M$220-ROW('QC Deviation Record Hall 2'!$M$119:$M$220)/10000000,ROW(A2)),'QC Deviation Record Hall 2'!$M$119:$M$220-ROW('QC Deviation Record Hall 2'!$M$119:$M$220)/10000000,0))} -> إضافات رطبة/مكسورة زيادة | T35: {=INDEX('QC Deviation Record Hall 2'!$C$119:$C$220,MATCH(Table11[[#This Row],[Defect العيب]],'QC Deviation Record Hall 2'!$B$119:$B$220,0))} | U35: {=INDEX('QC Deviation Record Hall 2'!$D$119:$D$220,MATCH(Table11[[#This Row],[Defect العيب]],'QC Deviation Record Hall 2'!$B$119:$B$220,0))} | V35: {=INDEX('QC Deviation Record Hall 2'!$E$119:$E$220,MATCH(Table11[[#This Row],[Defect العيب]],'QC Deviation Record Hall 2'!$B$119:$B$220,0))} | W35: {=INDEX('QC Deviation Record Hall 2'!$F$119:$F$220,MATCH(Table11[[#This Row],[Defect العيب]],'QC Deviation Record Hall 2'!$B$119:$B$220,0))} | X35: {=INDEX('QC Deviation Record Hall 2'!$G$119:$G$220,MATCH(Table11[[#This Row],[Defect العيب]],'QC Deviation Record Hall 2'!$B$119:$B$220,0))} | Y35: {=INDEX('QC Deviation Record Hall 2'!$H$119:$H$220,MATCH(Table11[[#This Row],[Defect العيب]],'QC Deviation Record Hall 2'!$B$119:$B$220,0))} | Z35: {=INDEX('QC Deviation Record Hall 2'!$I$119:$I$220,MATCH(Table11[[#This Row],[Defect العيب]],'QC Deviation Record Hall 2'!$B$119:$B$220,0))} | AA35: {=INDEX('QC Deviation Record Hall 2'!$J$119:$J$220,MATCH(Table11[[#This Row],[Defect العيب]],'QC Deviation Record Hall 2'!$B$119:$B$220,0))} | AB35: {=INDEX('QC Deviation Record Hall 2'!$K$119:$K$220,MATCH(Table11[[#This Row],[Defect العيب]],'QC Deviation Record Hall 2'!$B$119:$B$220,0))} | AC35: {=INDEX('QC Deviation Record Hall 2'!$L$119:$L$220,MATCH(Table11[[#This Row],[Defect العيب]],'QC Deviation Record Hall 2'!$B$119:$B$220,0))} | AF35: {=INDEX('QC Deviation Record Hall 3'!$A$119:$A$220,MATCH(Table111[[#This Row],[Defect العيب]],'QC Deviation Record Hall 3'!$B$119:$B$220,0))} -> AD02 | AG35: {=INDEX('QC Deviation Record Hall 3'!$B$119:$B$220,MATCH(LARGE('QC Deviation Record Hall 3'!$M$119:$M$220-ROW('QC Deviation Record Hall 3'!$M$119:$M$220)/10000000,ROW(A2)),'QC Deviation Record Hall 3'!$M$119:$M$220-ROW('QC Deviation Record Hall 3'!$M$119:$M$220)/10000000,0))} -> إضافات رطبة/مكسورة زيادة | AI35: {=INDEX('QC Deviation Record Hall 3'!$C$119:$C$220,MATCH(Table111[[#This Row],[Defect العيب]],'QC Deviation Record Hall 3'!$B$119:$B$220,0))} | AJ35: {=INDEX('QC Deviation Record Hall 3'!$D$119:$D$220,MATCH(Table111[[#This Row],[Defect العيب]],'QC Deviation Record Hall 3'!$B$119:$B$220,0))} | AK35: {=INDEX('QC Deviation Record Hall 3'!$E$119:$E$220,MATCH(Table111[[#This Row],[Defect العيب]],'QC Deviation Record Hall 3'!$B$119:$B$220,0))} | AL35: {=INDEX('QC Deviation Record Hall 3'!$F$119:$F$220,MATCH(Table111[[#This Row],[Defect العيب]],'QC Deviation Record Hall 3'!$B$119:$B$220,0))} | AM35: {=INDEX('QC Deviation Record Hall 3'!$G$119:$G$220,MATCH(Table111[[#This Row],[Defect العيب]],'QC Deviation Record Hall 3'!$B$119:$B$220,0))} | AN35: {=INDEX('QC Deviation Record Hall 3'!$H$119:$H$220,MATCH(Table111[[#This Row],[Defect العيب]],'QC Deviation Record Hall 3'!$B$119:$B$220,0))} | AO35: {=INDEX('QC Deviation Record Hall 3'!$I$119:$I$220,MATCH(Table111[[#This Row],[Defect العيب]],'QC Deviation Record Hall 3'!$B$119:$B$220,0))} | AP35: {=INDEX('QC Deviation Record Hall 3'!$J$119:$J$220,MATCH(Table111[[#This Row],[Defect العيب]],'QC Deviation Record Hall 3'!$B$119:$B$220,0))} | AQ35: {=INDEX('QC Deviation Record Hall 3'!$K$119:$K$220,MATCH(Table111[[#This Row],[Defect العيب]],'QC Deviation Record Hall 3'!$B$119:$B$220,0))} | AR35: {=INDEX('QC Deviation Record Hall 3'!$L$119:$L$220,MATCH(Table111[[#This Row],[Defect العيب]],'QC Deviation Record Hall 3'!$B$119:$B$220,0))}
A36: {=INDEX('QC Deviation Record Hall 1 '!$A$120:$A$221,MATCH(Table7[[#This Row],[Defect العيب]],'QC Deviation Record Hall 1 '!$B$120:$B$221,0))} -> AD02 | B36: {=INDEX('QC Deviation Record Hall 1 '!$B$120:$B$221,MATCH(LARGE('QC Deviation Record Hall 1 '!$O$120:$O$221-ROW('QC Deviation Record Hall 1 '!$O$120:$O$221)/10000000,ROW(A2)),'QC Deviation Record Hall 1 '!$O$120:$O$221-ROW('QC Deviation Record Hall 1 '!$O$120:$O$221)/10000000,0))} -> إضافات رطبة/مكسورة زيادة | D36: {=INDEX('QC Deviation Record Hall 1 '!$C$120:$C$221,MATCH(Table7[[#This Row],[Defect العيب]],'QC Deviation Record Hall 1 '!$B$120:$B$221,0))} | E36: {=INDEX('QC Deviation Record Hall 1 '!$D$120:$D$221,MATCH(Table7[[#This Row],[Defect العيب]],'QC Deviation Record Hall 1 '!$B$120:$B$221,0))} | F36: {=INDEX('QC Deviation Record Hall 1 '!$E$120:$E$221,MATCH(Table7[[#This Row],[Defect العيب]],'QC Deviation Record Hall 1 '!$B$120:$B$221,0))} | G36: {=INDEX('QC Deviation Record Hall 1 '!$F$120:$F$221,MATCH(Table7[[#This Row],[Defect العيب]],'QC Deviation Record Hall 1 '!$B$120:$B$221,0))} | H36: {=INDEX('QC Deviation Record Hall 1 '!$G$120:$G$221,MATCH(Table7[[#This Row],[Defect العيب]],'QC Deviation Record Hall 1 '!$B$120:$B$221,0))} | I36: {=INDEX('QC Deviation Record Hall 1 '!$H$120:$H$221,MATCH(Table7[[#This Row],[Defect العيب]],'QC Deviation Record Hall 1 '!$B$120:$B$221,0))} | J36: {=INDEX('QC Deviation Record Hall 1 '!$I$120:$I$221,MATCH(Table7[[#This Row],[Defect العيب]],'QC Deviation Record Hall 1 '!$B$120:$B$221,0))} | K36: {=INDEX('QC Deviation Record Hall 1 '!$J$120:$J$221,MATCH(Table7[[#This Row],[Defect العيب]],'QC Deviation Record Hall 1 '!$B$120:$B$221,0))} | L36: {=INDEX('QC Deviation Record Hall 1 '!$K$120:$K$221,MATCH(Table7[[#This Row],[Defect العيب]],'QC Deviation Record Hall 1 '!$B$120:$B$221,0))} | M36: {=INDEX('QC Deviation Record Hall 1 '!$L$120:$L$221,MATCH(Table7[[#This Row],[Defect العيب]],'QC Deviation Record Hall 1 '!$B$120:$B$221,0))} | N36: {=INDEX('QC Deviation Record Hall 1 '!$M$120:$M$221,MATCH(Table7[[#This Row],[Defect العيب]],'QC Deviation Record Hall 1 '!$B$120:$B$221,0))} | O36: {=INDEX('QC Deviation Record Hall 1 '!$N$120:$N$221,MATCH(Table7[[#This Row],[Defect العيب]],'QC Deviation Record Hall 1 '!$B$120:$B$221,0))} | Q36: {=INDEX('QC Deviation Record Hall 2'!$A$119:$A$220,MATCH(Table11[[#This Row],[Defect العيب]],'QC Deviation Record Hall 2'!$B$119:$B$220,0))} -> AD02 | R36: {=INDEX('QC Deviation Record Hall 2'!$B$119:$B$220,MATCH(LARGE('QC Deviation Record Hall 2'!$M$119:$M$220-ROW('QC Deviation Record Hall 2'!$M$119:$M$220)/10000000,ROW(A2)),'QC Deviation Record Hall 2'!$M$119:$M$220-ROW('QC Deviation Record Hall 2'!$M$119:$M$220)/10000000,0))} -> إضافات رطبة/مكسورة زيادة | T36: {=INDEX('QC Deviation Record Hall 2'!$C$119:$C$220,MATCH(Table11[[#This Row],[Defect العيب]],'QC Deviation Record Hall 2'!$B$119:$B$220,0))} | U36: {=INDEX('QC Deviation Record Hall 2'!$D$119:$D$220,MATCH(Table11[[#This Row],[Defect العيب]],'QC Deviation Record Hall 2'!$B$119:$B$220,0))} | V36: {=INDEX('QC Deviation Record Hall 2'!$E$119:$E$220,MATCH(Table11[[#This Row],[Defect العيب]],'QC Deviation Record Hall 2'!$B$119:$B$220,0))} | W36: {=INDEX('QC Deviation Record Hall 2'!$F$119:$F$220,MATCH(Table11[[#This Row],[Defect العيب]],'QC Deviation Record Hall 2'!$B$119:$B$220,0))} | X36: {=INDEX('QC Deviation Record Hall 2'!$G$119:$G$220,MATCH(Table11[[#This Row],[Defect العيب]],'QC Deviation Record Hall 2'!$B$119:$B$220,0))} | Y36: {=INDEX('QC Deviation Record Hall 2'!$H$119:$H$220,MATCH(Table11[[#This Row],[Defect العيب]],'QC Deviation Record Hall 2'!$B$119:$B$220,0))} | Z36: {=INDEX('QC Deviation Record Hall 2'!$I$119:$I$220,MATCH(Table11[[#This Row],[Defect العيب]],'QC Deviation Record Hall 2'!$B$119:$B$220,0))} | AA36: {=INDEX('QC Deviation Record Hall 2'!$J$119:$J$220,MATCH(Table11[[#This Row],[Defect العيب]],'QC Deviation Record Hall 2'!$B$119:$B$220,0))} | AB36: {=INDEX('QC Deviation Record Hall 2'!$K$119:$K$220,MATCH(Table11[[#This Row],[Defect العيب]],'QC Deviation Record Hall 2'!$B$119:$B$220,0))} | AC36: {=INDEX('QC Deviation Record Hall 2'!$L$119:$L$220,MATCH(Table11[[#This Row],[Defect العيب]],'QC Deviation Record Hall 2'!$B$119:$B$220,0))} | AF36: {=INDEX('QC Deviation Record Hall 3'!$A$119:$A$220,MATCH(Table111[[#This Row],[Defect العيب]],'QC Deviation Record Hall 3'!$B$119:$B$220,0))} -> AD02 | AG36: {=INDEX('QC Deviation Record Hall 3'!$B$119:$B$220,MATCH(LARGE('QC Deviation Record Hall 3'!$M$119:$M$220-ROW('QC Deviation Record Hall 3'!$M$119:$M$220)/10000000,ROW(A2)),'QC Deviation Record Hall 3'!$M$119:$M$220-ROW('QC Deviation Record Hall 3'!$M$119:$M$220)/10000000,0))} -> إضافات رطبة/مكسورة زيادة | AI36: {=INDEX('QC Deviation Record Hall 3'!$C$119:$C$220,MATCH(Table111[[#This Row],[Defect العيب]],'QC Deviation Record Hall 3'!$B$119:$B$220,0))} | AJ36: {=INDEX('QC Deviation Record Hall 3'!$D$119:$D$220,MATCH(Table111[[#This Row],[Defect العيب]],'QC Deviation Record Hall 3'!$B$119:$B$220,0))} | AK36: {=INDEX('QC Deviation Record Hall 3'!$E$119:$E$220,MATCH(Table111[[#This Row],[Defect العيب]],'QC Deviation Record Hall 3'!$B$119:$B$220,0))} | AL36: {=INDEX('QC Deviation Record Hall 3'!$F$119:$F$220,MATCH(Table111[[#This Row],[Defect العيب]],'QC Deviation Record Hall 3'!$B$119:$B$220,0))} | AM36: {=INDEX('QC Deviation Record Hall 3'!$G$119:$G$220,MATCH(Table111[[#This Row],[Defect العيب]],'QC Deviation Record Hall 3'!$B$119:$B$220,0))} | AN36: {=INDEX('QC Deviation Record Hall 3'!$H$119:$H$220,MATCH(Table111[[#This Row],[Defect العيب]],'QC Deviation Record Hall 3'!$B$119:$B$220,0))} | AO36: {=INDEX('QC Deviation Record Hall 3'!$I$119:$I$220,MATCH(Table111[[#This Row],[Defect العيب]],'QC Deviation Record Hall 3'!$B$119:$B$220,0))} | AP36: {=INDEX('QC Deviation Record Hall 3'!$J$119:$J$220,MATCH(Table111[[#This Row],[Defect العيب]],'QC Deviation Record Hall 3'!$B$119:$B$220,0))} | AQ36: {=INDEX('QC Deviation Record Hall 3'!$K$119:$K$220,MATCH(Table111[[#This Row],[Defect العيب]],'QC Deviation Record Hall 3'!$B$119:$B$220,0))} | AR36: {=INDEX('QC Deviation Record Hall 3'!$L$119:$L$220,MATCH(Table111[[#This Row],[Defect العيب]],'QC Deviation Record Hall 3'!$B$119:$B$220,0))}
A37: {=INDEX('QC Deviation Record Hall 1 '!$A$120:$A$221,MATCH(Table7[[#This Row],[Defect العيب]],'QC Deviation Record Hall 1 '!$B$120:$B$221,0))} -> AD03 | B37: {=INDEX('QC Deviation Record Hall 1 '!$B$120:$B$221,MATCH(LARGE('QC Deviation Record Hall 1 '!$O$120:$O$221-ROW('QC Deviation Record Hall 1 '!$O$120:$O$221)/10000000,ROW(A3)),'QC Deviation Record Hall 1 '!$O$120:$O$221-ROW('QC Deviation Record Hall 1 '!$O$120:$O$221)/10000000,0))} -> نوع إضافات غير مطابق للوصفة | D37: {=INDEX('QC Deviation Record Hall 1 '!$C$120:$C$221,MATCH(Table7[[#This Row],[Defect العيب]],'QC Deviation Record Hall 1 '!$B$120:$B$221,0))} | E37: {=INDEX('QC Deviation Record Hall 1 '!$D$120:$D$221,MATCH(Table7[[#This Row],[Defect العيب]],'QC Deviation Record Hall 1 '!$B$120:$B$221,0))} | F37: {=INDEX('QC Deviation Record Hall 1 '!$E$120:$E$221,MATCH(Table7[[#This Row],[Defect العيب]],'QC Deviation Record Hall 1 '!$B$120:$B$221,0))} | G37: {=INDEX('QC Deviation Record Hall 1 '!$F$120:$F$221,MATCH(Table7[[#This Row],[Defect العيب]],'QC Deviation Record Hall 1 '!$B$120:$B$221,0))} | H37: {=INDEX('QC Deviation Record Hall 1 '!$G$120:$G$221,MATCH(Table7[[#This Row],[Defect العيب]],'QC Deviation Record Hall 1 '!$B$120:$B$221,0))} | I37: {=INDEX('QC Deviation Record Hall 1 '!$H$120:$H$221,MATCH(Table7[[#This Row],[Defect العيب]],'QC Deviation Record Hall 1 '!$B$120:$B$221,0))} | J37: {=INDEX('QC Deviation Record Hall 1 '!$I$120:$I$221,MATCH(Table7[[#This Row],[Defect العيب]],'QC Deviation Record Hall 1 '!$B$120:$B$221,0))} | K37: {=INDEX('QC Deviation Record Hall 1 '!$J$120:$J$221,MATCH(Table7[[#This Row],[Defect العيب]],'QC Deviation Record Hall 1 '!$B$120:$B$221,0))} | L37: {=INDEX('QC Deviation Record Hall 1 '!$K$120:$K$221,MATCH(Table7[[#This Row],[Defect العيب]],'QC Deviation Record Hall 1 '!$B$120:$B$221,0))} | M37: {=INDEX('QC Deviation Record Hall 1 '!$L$120:$L$221,MATCH(Table7[[#This Row],[Defect العيب]],'QC Deviation Record Hall 1 '!$B$120:$B$221,0))} | N37: {=INDEX('QC Deviation Record Hall 1 '!$M$120:$M$221,MATCH(Table7[[#This Row],[Defect العيب]],'QC Deviation Record Hall 1 '!$B$120:$B$221,0))} | O37: {=INDEX('QC Deviation Record Hall 1 '!$N$120:$N$221,MATCH(Table7[[#This Row],[Defect العيب]],'QC Deviation Record Hall 1 '!$B$120:$B$221,0))} | Q37: {=INDEX('QC Deviation Record Hall 2'!$A$119:$A$220,MATCH(Table11[[#This Row],[Defect العيب]],'QC Deviation Record Hall 2'!$B$119:$B$220,0))} -> AD03 | R37: {=INDEX('QC Deviation Record Hall 2'!$B$119:$B$220,MATCH(LARGE('QC Deviation Record Hall 2'!$M$119:$M$220-ROW('QC Deviation Record Hall 2'!$M$119:$M$220)/10000000,ROW(A3)),'QC Deviation Record Hall 2'!$M$119:$M$220-ROW('QC Deviation Record Hall 2'!$M$119:$M$220)/10000000,0))} -> نوع إضافات غير مطابق للوصفة | T37: {=INDEX('QC Deviation Record Hall 2'!$C$119:$C$220,MATCH(Table11[[#This Row],[Defect العيب]],'QC Deviation Record Hall 2'!$B$119:$B$220,0))} | U37: {=INDEX('QC Deviation Record Hall 2'!$D$119:$D$220,MATCH(Table11[[#This Row],[Defect العيب]],'QC Deviation Record Hall 2'!$B$119:$B$220,0))} | V37: {=INDEX('QC Deviation Record Hall 2'!$E$119:$E$220,MATCH(Table11[[#This Row],[Defect العيب]],'QC Deviation Record Hall 2'!$B$119:$B$220,0))} | W37: {=INDEX('QC Deviation Record Hall 2'!$F$119:$F$220,MATCH(Table11[[#This Row],[Defect العيب]],'QC Deviation Record Hall 2'!$B$119:$B$220,0))} | X37: {=INDEX('QC Deviation Record Hall 2'!$G$119:$G$220,MATCH(Table11[[#This Row],[Defect العيب]],'QC Deviation Record Hall 2'!$B$119:$B$220,0))} | Y37: {=INDEX('QC Deviation Record Hall 2'!$H$119:$H$220,MATCH(Table11[[#This Row],[Defect العيب]],'QC Deviation Record Hall 2'!$B$119:$B$220,0))} | Z37: {=INDEX('QC Deviation Record Hall 2'!$I$119:$I$220,MATCH(Table11[[#This Row],[Defect العيب]],'QC Deviation Record Hall 2'!$B$119:$B$220,0))} | AA37: {=INDEX('QC Deviation Record Hall 2'!$J$119:$J$220,MATCH(Table11[[#This Row],[Defect العيب]],'QC Deviation Record Hall 2'!$B$119:$B$220,0))} | AB37: {=INDEX('QC Deviation Record Hall 2'!$K$119:$K$220,MATCH(Table11[[#This Row],[Defect العيب]],'QC Deviation Record Hall 2'!$B$119:$B$220,0))} | AC37: {=INDEX('QC Deviation Record Hall 2'!$L$119:$L$220,MATCH(Table11[[#This Row],[Defect العيب]],'QC Deviation Record Hall 2'!$B$119:$B$220,0))} | AF37: {=INDEX('QC Deviation Record Hall 3'!$A$119:$A$220,MATCH(Table111[[#This Row],[Defect العيب]],'QC Deviation Record Hall 3'!$B$119:$B$220,0))} -> AD03 | AG37: {=INDEX('QC Deviation Record Hall 3'!$B$119:$B$220,MATCH(LARGE('QC Deviation Record Hall 3'!$M$119:$M$220-ROW('QC Deviation Record Hall 3'!$M$119:$M$220)/10000000,ROW(A3)),'QC Deviation Record Hall 3'!$M$119:$M$220-ROW('QC Deviation Record Hall 3'!$M$119:$M$220)/10000000,0))} -> نوع إضافات غير مطابق للوصفة | AI37: {=INDEX('QC Deviation Record Hall 3'!$C$119:$C$220,MATCH(Table111[[#This Row],[Defect العيب]],'QC Deviation Record Hall 3'!$B$119:$B$220,0))} | AJ37: {=INDEX('QC Deviation Record Hall 3'!$D$119:$D$220,MATCH(Table111[[#This Row],[Defect العيب]],'QC Deviation Record Hall 3'!$B$119:$B$220,0))} | AK37: {=INDEX('QC Deviation Record Hall 3'!$E$119:$E$220,MATCH(Table111[[#This Row],[Defect العيب]],'QC Deviation Record Hall 3'!$B$119:$B$220,0))} | AL37: {=INDEX('QC Deviation Record Hall 3'!$F$119:$F$220,MATCH(Table111[[#This Row],[Defect العيب]],'QC Deviation Record Hall 3'!$B$119:$B$220,0))} | AM37: {=INDEX('QC Deviation Record Hall 3'!$G$119:$G$220,MATCH(Table111[[#This Row],[Defect العيب]],'QC Deviation Record Hall 3'!$B$119:$B$220,0))} | AN37: {=INDEX('QC Deviation Record Hall 3'!$H$119:$H$220,MATCH(Table111[[#This Row],[Defect العيب]],'QC Deviation Record Hall 3'!$B$119:$B$220,0))} | AO37: {=INDEX('QC Deviation Record Hall 3'!$I$119:$I$220,MATCH(Table111[[#This Row],[Defect العيب]],'QC Deviation Record Hall 3'!$B$119:$B$220,0))} | AP37: {=INDEX('QC Deviation Record Hall 3'!$J$119:$J$220,MATCH(Table111[[#This Row],[Defect العيب]],'QC Deviation Record Hall 3'!$B$119:$B$220,0))} | AQ37: {=INDEX('QC Deviation Record Hall 3'!$K$119:$K$220,MATCH(Table111[[#This Row],[Defect العيب]],'QC Deviation Record Hall 3'!$B$119:$B$220,0))} | AR37: {=INDEX('QC Deviation Record Hall 3'!$L$119:$L$220,MATCH(Table111[[#This Row],[Defect العيب]],'QC Deviation Record Hall 3'!$B$119:$B$220,0))}
A38: {=INDEX('QC Deviation Record Hall 1 '!$A$120:$A$221,MATCH(Table7[[#This Row],[Defect العيب]],'QC Deviation Record Hall 1 '!$B$120:$B$221,0))} -> AD04 | B38: {=INDEX('QC Deviation Record Hall 1 '!$B$120:$B$221,MATCH(LARGE('QC Deviation Record Hall 1 '!$O$120:$O$221-ROW('QC Deviation Record Hall 1 '!$O$120:$O$221)/10000000,ROW(A4)),'QC Deviation Record Hall 1 '!$O$120:$O$221-ROW('QC Deviation Record Hall 1 '!$O$120:$O$221)/10000000,0))} -> عدم وجود إضافة / إنسداد فى كل العيون | D38: {=INDEX('QC Deviation Record Hall 1 '!$C$120:$C$221,MATCH(Table7[[#This Row],[Defect العيب]],'QC Deviation Record Hall 1 '!$B$120:$B$221,0))} | E38: {=INDEX('QC Deviation Record Hall 1 '!$D$120:$D$221,MATCH(Table7[[#This Row],[Defect العيب]],'QC Deviation Record Hall 1 '!$B$120:$B$221,0))} | F38: {=INDEX('QC Deviation Record Hall 1 '!$E$120:$E$221,MATCH(Table7[[#This Row],[Defect العيب]],'QC Deviation Record Hall 1 '!$B$120:$B$221,0))} | G38: {=INDEX('QC Deviation Record Hall 1 '!$F$120:$F$221,MATCH(Table7[[#This Row],[Defect العيب]],'QC Deviation Record Hall 1 '!$B$120:$B$221,0))} | H38: {=INDEX('QC Deviation Record Hall 1 '!$G$120:$G$221,MATCH(Table7[[#This Row],[Defect العيب]],'QC Deviation Record Hall 1 '!$B$120:$B$221,0))} | I38: {=INDEX('QC Deviation Record Hall 1 '!$H$120:$H$221,MATCH(Table7[[#This Row],[Defect العيب]],'QC Deviation Record Hall 1 '!$B$120:$B$221,0))} | J38: {=INDEX('QC Deviation Record Hall 1 '!$I$120:$I$221,MATCH(Table7[[#This Row],[Defect العيب]],'QC Deviation Record Hall 1 '!$B$120:$B$221,0))} | K38: {=INDEX('QC Deviation Record Hall 1 '!$J$120:$J$221,MATCH(Table7[[#This Row],[Defect العيب]],'QC Deviation Record Hall 1 '!$B$120:$B$221,0))} | L38: {=INDEX('QC Deviation Record Hall 1 '!$K$120:$K$221,MATCH(Table7[[#This Row],[Defect العيب]],'QC Deviation Record Hall 1 '!$B$120:$B$221,0))} | M38: {=INDEX('QC Deviation Record Hall 1 '!$L$120:$L$221,MATCH(Table7[[#This Row],[Defect العيب]],'QC Deviation Record Hall 1 '!$B$120:$B$221,0))} | N38: {=INDEX('QC Deviation Record Hall 1 '!$M$120:$M$221,MATCH(Table7[[#This Row],[Defect العيب]],'QC Deviation Record Hall 1 '!$B$120:$B$221,0))} | O38: {=INDEX('QC Deviation Record Hall 1 '!$N$120:$N$221,MATCH(Table7[[#This Row],[Defect العيب]],'QC Deviation Record Hall 1 '!$B$120:$B$221,0))} | Q38: {=INDEX('QC Deviation Record Hall 2'!$A$119:$A$220,MATCH(Table11[[#This Row],[Defect العيب]],'QC Deviation Record Hall 2'!$B$119:$B$220,0))} -> AD04 | R38: {=INDEX('QC Deviation Record Hall 2'!$B$119:$B$220,MATCH(LARGE('QC Deviation Record Hall 2'!$M$119:$M$220-ROW('QC Deviation Record Hall 2'!$M$119:$M$220)/10000000,ROW(A4)),'QC Deviation Record Hall 2'!$M$119:$M$220-ROW('QC Deviation Record Hall 2'!$M$119:$M$220)/10000000,0))} -> عدم وجود إضافة / إنسداد فى كل العيون | T38: {=INDEX('QC Deviation Record Hall 2'!$C$119:$C$220,MATCH(Table11[[#This Row],[Defect العيب]],'QC Deviation Record Hall 2'!$B$119:$B$220,0))} | U38: {=INDEX('QC Deviation Record Hall 2'!$D$119:$D$220,MATCH(Table11[[#This Row],[Defect العيب]],'QC Deviation Record Hall 2'!$B$119:$B$220,0))} | V38: {=INDEX('QC Deviation Record Hall 2'!$E$119:$E$220,MATCH(Table11[[#This Row],[Defect العيب]],'QC Deviation Record Hall 2'!$B$119:$B$220,0))} | W38: {=INDEX('QC Deviation Record Hall 2'!$F$119:$F$220,MATCH(Table11[[#This Row],[Defect العيب]],'QC Deviation Record Hall 2'!$B$119:$B$220,0))} | X38: {=INDEX('QC Deviation Record Hall 2'!$G$119:$G$220,MATCH(Table11[[#This Row],[Defect العيب]],'QC Deviation Record Hall 2'!$B$119:$B$220,0))} | Y38: {=INDEX('QC Deviation Record Hall 2'!$H$119:$H$220,MATCH(Table11[[#This Row],[Defect العيب]],'QC Deviation Record Hall 2'!$B$119:$B$220,0))} | Z38: {=INDEX('QC Deviation Record Hall 2'!$I$119:$I$220,MATCH(Table11[[#This Row],[Defect العيب]],'QC Deviation Record Hall 2'!$B$119:$B$220,0))} | AA38: {=INDEX('QC Deviation Record Hall 2'!$J$119:$J$220,MATCH(Table11[[#This Row],[Defect العيب]],'QC Deviation Record Hall 2'!$B$119:$B$220,0))} | AB38: {=INDEX('QC Deviation Record Hall 2'!$K$119:$K$220,MATCH(Table11[[#This Row],[Defect العيب]],'QC Deviation Record Hall 2'!$B$119:$B$220,0))} | AC38: {=INDEX('QC Deviation Record Hall 2'!$L$119:$L$220,MATCH(Table11[[#This Row],[Defect العيب]],'QC Deviation Record Hall 2'!$B$119:$B$220,0))} | AF38: {=INDEX('QC Deviation Record Hall 3'!$A$119:$A$220,MATCH(Table111[[#This Row],[Defect العيب]],'QC Deviation Record Hall 3'!$B$119:$B$220,0))} -> AD04 | AG38: {=INDEX('QC Deviation Record Hall 3'!$B$119:$B$220,MATCH(LARGE('QC Deviation Record Hall 3'!$M$119:$M$220-ROW('QC Deviation Record Hall 3'!$M$119:$M$220)/10000000,ROW(A4)),'QC Deviation Record Hall 3'!$M$119:$M$220-ROW('QC Deviation Record Hall 3'!$M$119:$M$220)/10000000,0))} -> عدم وجود إضافة / إنسداد فى كل العيون | AI38: {=INDEX('QC Deviation Record Hall 3'!$C$119:$C$220,MATCH(Table111[[#This Row],[Defect العيب]],'QC Deviation Record Hall 3'!$B$119:$B$220,0))} | AJ38: {=INDEX('QC Deviation Record Hall 3'!$D$119:$D$220,MATCH(Table111[[#This Row],[Defect العيب]],'QC Deviation Record Hall 3'!$B$119:$B$220,0))} | AK38: {=INDEX('QC Deviation Record Hall 3'!$E$119:$E$220,MATCH(Table111[[#This Row],[Defect العيب]],'QC Deviation Record Hall 3'!$B$119:$B$220,0))} | AL38: {=INDEX('QC Deviation Record Hall 3'!$F$119:$F$220,MATCH(Table111[[#This Row],[Defect العيب]],'QC Deviation Record Hall 3'!$B$119:$B$220,0))} | AM38: {=INDEX('QC Deviation Record Hall 3'!$G$119:$G$220,MATCH(Table111[[#This Row],[Defect العيب]],'QC Deviation Record Hall 3'!$B$119:$B$220,0))} | AN38: {=INDEX('QC Deviation Record Hall 3'!$H$119:$H$220,MATCH(Table111[[#This Row],[Defect العيب]],'QC Deviation Record Hall 3'!$B$119:$B$220,0))} | AO38: {=INDEX('QC Deviation Record Hall 3'!$I$119:$I$220,MATCH(Table111[[#This Row],[Defect العيب]],'QC Deviation Record Hall 3'!$B$119:$B$220,0))} | AP38: {=INDEX('QC Deviation Record Hall 3'!$J$119:$J$220,MATCH(Table111[[#This Row],[Defect العيب]],'QC Deviation Record Hall 3'!$B$119:$B$220,0))} | AQ38: {=INDEX('QC Deviation Record Hall 3'!$K$119:$K$220,MATCH(Table111[[#This Row],[Defect العيب]],'QC Deviation Record Hall 3'!$B$119:$B$220,0))} | AR38: {=INDEX('QC Deviation Record Hall 3'!$L$119:$L$220,MATCH(Table111[[#This Row],[Defect العيب]],'QC Deviation Record Hall 3'!$B$119:$B$220,0))}
